Traceback (most recent call last):
  File "C:\Users\vanna\.conda\envs\.env\Lib\site-packages\jupyter_cache\executors\utils.py", line 58, in single_nb_execution
    executenb(
  File "C:\Users\vanna\.conda\envs\.env\Lib\site-packages\nbclient\client.py", line 1314, in execute
    return NotebookClient(nb=nb, resources=resources, km=km, **kwargs).execute()
           ^^^^^^^^^^^^^^^^^^^^^^^^^^^^^^^^^^^^^^^^^^^^^^^^^^^^^^^^^^^^^^^^^^^^^
  File "C:\Users\vanna\.conda\envs\.env\Lib\site-packages\jupyter_core\utils\__init__.py", line 165, in wrapped
    return loop.run_until_complete(inner)
           ^^^^^^^^^^^^^^^^^^^^^^^^^^^^^^
  File "C:\Users\vanna\.conda\envs\.env\Lib\asyncio\base_events.py", line 684, in run_until_complete
    return future.result()
           ^^^^^^^^^^^^^^^
  File "C:\Users\vanna\.conda\envs\.env\Lib\site-packages\nbclient\client.py", line 709, in async_execute
    await self.async_execute_cell(
  File "C:\Users\vanna\.conda\envs\.env\Lib\site-packages\nbclient\client.py", line 1062, in async_execute_cell
    await self._check_raise_for_error(cell, cell_index, exec_reply)
  File "C:\Users\vanna\.conda\envs\.env\Lib\site-packages\nbclient\client.py", line 918, in _check_raise_for_error
    raise CellExecutionError.from_cell_and_msg(cell, exec_reply_content)
nbclient.exceptions.CellExecutionError: An error occurred while executing the following cell:
------------------
import data_module_test.addition as addition

addition.add(10,20)
addition.add(30,40)
------------------


[1;31m---------------------------------------------------------------------------[0m
[1;31mModuleNotFoundError[0m                       Traceback (most recent call last)
Cell [1;32mIn[2], line 1[0m
[1;32m----> 1[0m [38;5;28;01mimport[39;00m [38;5;21;01mdata_module_test[39;00m[38;5;21;01m.[39;00m[38;5;21;01maddition[39;00m [38;5;28;01mas[39;00m [38;5;21;01maddition[39;00m
[0;32m      3[0m addition[38;5;241m.[39madd([38;5;241m10[39m,[38;5;241m20[39m)
[0;32m      4[0m addition[38;5;241m.[39madd([38;5;241m30[39m,[38;5;241m40[39m)

[1;31mModuleNotFoundError[0m: No module named 'data_module_test'

