Traceback (most recent call last):
  File "C:\Users\vanna\.conda\envs\.env\Lib\site-packages\jupyter_cache\executors\utils.py", line 58, in single_nb_execution
    executenb(
  File "C:\Users\vanna\.conda\envs\.env\Lib\site-packages\nbclient\client.py", line 1314, in execute
    return NotebookClient(nb=nb, resources=resources, km=km, **kwargs).execute()
           ^^^^^^^^^^^^^^^^^^^^^^^^^^^^^^^^^^^^^^^^^^^^^^^^^^^^^^^^^^^^^^^^^^^^^
  File "C:\Users\vanna\.conda\envs\.env\Lib\site-packages\jupyter_core\utils\__init__.py", line 165, in wrapped
    return loop.run_until_complete(inner)
           ^^^^^^^^^^^^^^^^^^^^^^^^^^^^^^
  File "C:\Users\vanna\.conda\envs\.env\Lib\asyncio\base_events.py", line 684, in run_until_complete
    return future.result()
           ^^^^^^^^^^^^^^^
  File "C:\Users\vanna\.conda\envs\.env\Lib\site-packages\nbclient\client.py", line 709, in async_execute
    await self.async_execute_cell(
  File "C:\Users\vanna\.conda\envs\.env\Lib\site-packages\nbclient\client.py", line 1062, in async_execute_cell
    await self._check_raise_for_error(cell, cell_index, exec_reply)
  File "C:\Users\vanna\.conda\envs\.env\Lib\site-packages\nbclient\client.py", line 918, in _check_raise_for_error
    raise CellExecutionError.from_cell_and_msg(cell, exec_reply_content)
nbclient.exceptions.CellExecutionError: An error occurred while executing the following cell:
------------------
# doc file txt va chuyen thanh mang np

with open(r'../sources/heights_1.txt', 'r') as f:
  heights = f.read().replace("[", "").replace("]", "").split(', ')
np_heights = np.array(heights)
np_heights = np_heights.astype(int)
print(np_heights)
print(np_heights.shape)

with open(r'../sources/weights_1.txt', 'r') as f:
  weights_1 = f.read().replace("[", "").replace("]", "").split(', ')
np_weights = np.array(weights_1)
np_weights = np_weights.astype(int)
print(np_weights)
print(np_weights.shape)
------------------


[1;31m--------------------------------------------------------------------------[0m
[1;31mFileNotFoundError[0m                        Traceback (most recent call last)
Cell [1;32mIn[6], line 3[0m
[0;32m      1[0m [38;5;66;03m# doc file txt va chuyen thanh mang np[39;00m
[1;32m----> 3[0m [38;5;28;01mwith[39;00m [38;5;28;43mopen[39;49m[43m([49m[38;5;124;43mr[39;49m[38;5;124;43m'[39;49m[38;5;124;43m../sources/heights_1.txt[39;49m[38;5;124;43m'[39;49m[43m,[49m[43m [49m[38;5;124;43m'[39;49m[38;5;124;43mr[39;49m[38;5;124;43m'[39;49m[43m)[49m [38;5;28;01mas[39;00m f:
[0;32m      4[0m   heights [38;5;241m=[39m f[38;5;241m.[39mread()[38;5;241m.[39mreplace([38;5;124m"[39m[38;5;124m[[39m[38;5;124m"[39m, [38;5;124m"[39m[38;5;124m"[39m)[38;5;241m.[39mreplace([38;5;124m"[39m[38;5;124m][39m[38;5;124m"[39m, [38;5;124m"[39m[38;5;124m"[39m)[38;5;241m.[39msplit([38;5;124m'[39m[38;5;124m, [39m[38;5;124m'[39m)
[0;32m      5[0m np_heights [38;5;241m=[39m np[38;5;241m.[39marray(heights)

File [1;32m~\.conda\envs\.env\Lib\site-packages\IPython\core\interactiveshell.py:310[0m, in [0;36m_modified_open[1;34m(file, *args, **kwargs)[0m
[0;32m    303[0m [38;5;28;01mif[39;00m file [38;5;129;01min[39;00m {[38;5;241m0[39m, [38;5;241m1[39m, [38;5;241m2[39m}:
[0;32m    304[0m     [38;5;28;01mraise[39;00m [38;5;167;01mValueError[39;00m(
[0;32m    305[0m         [38;5;124mf[39m[38;5;124m"[39m[38;5;124mIPython won[39m[38;5;124m'[39m[38;5;124mt let you open fd=[39m[38;5;132;01m{[39;00mfile[38;5;132;01m}[39;00m[38;5;124m by default [39m[38;5;124m"[39m
[0;32m    306[0m         [38;5;124m"[39m[38;5;124mas it is likely to crash IPython. If you know what you are doing, [39m[38;5;124m"[39m
[0;32m    307[0m         [38;5;124m"[39m[38;5;124myou can use builtins[39m[38;5;124m'[39m[38;5;124m open.[39m[38;5;124m"[39m
[0;32m    308[0m     )
[1;32m--> 310[0m [38;5;28;01mreturn[39;00m [43mio_open[49m[43m([49m[43mfile[49m[43m,[49m[43m [49m[38;5;241;43m*[39;49m[43margs[49m[43m,[49m[43m [49m[38;5;241;43m*[39;49m[38;5;241;43m*[39;49m[43mkwargs[49m[43m)[49m

[1;31mFileNotFoundError[0m: [Errno 2] No such file or directory: '../sources/heights_1.txt'

